<?xml version="1.0"?>
<robot xmlns:xacro="http://www.ros.org/wiki/xacro" name="arm">
    
    <xacro:include filename="$(find arm_description)/urdf/property.urdf.xacro"/>
    <xacro:include filename="$(find arm_description)/urdf/macro.urdf.xacro"/>

    <!-- Link -->
    <!-- ________________________________________________________________________________ -->
    <link name="world_link"/>

    <xacro:link name="holder_link" mass="5" mesh_path="package://arm_description/mesh/stand.STL" mesh_material="yelloworange"/>
    <!-- ________________________________________________________________________________ -->

    <xacro:link name="shoulder_Y_link" mass="1.5" mesh_path="package://arm_description/mesh/joint_shoulder_Y.STL" mesh_material="lightgrey"/>

    <!-- ________________________________________________________________________________ -->

    <xacro:link name="shoulder_X_link" mass="0.5" mesh_path="package://arm_description/mesh/joint_shoulder_X.STL" mesh_material="lightgrey"/>
    <!-- ________________________________________________________________________________ -->

    <xacro:link name="shoulder_link" mass="2" mesh_path="package://arm_description/mesh/shoulder.STL" mesh_material="blue"/>
    <!-- ________________________________________________________________________________ -->

    <xacro:link name="elbow_Z_link" mass="1.5" mesh_path="package://arm_description/mesh/joint_elbow_Z.STL" mesh_material="lightgrey"/>
    <!-- ________________________________________________________________________________ -->

    <xacro:link name="elbow_X_link" mass="0.5" mesh_path="package://arm_description/mesh/joint_elbow_X.STL" mesh_material="lightgrey"/>
    <!-- ________________________________________________________________________________ -->

    <xacro:link name="forearm_link" mass="1.5" mesh_path="package://arm_description/mesh/forearm.STL" mesh_material="blue"/>
    <!-- ________________________________________________________________________________ -->

    <xacro:link name="wrist_Z_link" mass="0.7" mesh_path="package://arm_description/mesh/joint_wrist_Z.STL" mesh_material="lightgrey"/>
    <!-- ________________________________________________________________________________ -->

    <xacro:link name="wrist_X_link" mass="0.2" mesh_path="package://arm_description/mesh/joint_wrist_X.STL" mesh_material="lightgrey"/>
    <!-- ________________________________________________________________________________ -->

    <xacro:link name="hand_link" mass="0.2" mesh_path="package://arm_description/mesh/hand.STL" mesh_material="blue"/>
    <!-- ________________________________________________________________________________ -->

    <xacro:link name="thumb_link" mass="0.01" mesh_path="package://arm_description/mesh/joint_thumb.STL" mesh_material="red"/>
    <!-- ________________________________________________________________________________ -->

    <xacro:link name="thumb_finger_link" mass="0.01" mesh_path="package://arm_description/mesh/joint_finger_thumb.STL" mesh_material="red"/>
    <!-- ________________________________________________________________________________ -->

    <xacro:link name="phalanx_thumb_1_link" mass="0.01" mesh_path="package://arm_description/mesh/phalanx_thumb_1.STL" mesh_material="red"/>
    <!-- ________________________________________________________________________________ -->

    <xacro:link name="phalanx_thumb_2_link" mass="0.01" mesh_path="package://arm_description/mesh/phalanx_thumb_2.STL" mesh_material="red"/>
    <!-- ________________________________________________________________________________ -->

    <xacro:link name="lit_finger_link" mass="0.01" mesh_path="package://arm_description/mesh/joint_finger.STL" mesh_material="red"/>
    <!-- ________________________________________________________________________________ -->

    <xacro:link name="phalanx_lit_finger_1_link" mass="0.01" mesh_path="package://arm_description/mesh/phalanx_lit_finger_1.STL" mesh_material="red"/>
    <!-- ________________________________________________________________________________ -->

    <xacro:link name="phalanx_lit_finger_2_link" mass="0.01" mesh_path="package://arm_description/mesh/phalanx_lit_finger_2.STL" mesh_material="red"/>
    <!-- ________________________________________________________________________________ -->

    <xacro:link name="phalanx_lit_finger_3_link" mass="0.01" mesh_path="package://arm_description/mesh/phalanx_lit_finger_3.STL" mesh_material="red"/>
    <!-- ________________________________________________________________________________ -->

    <xacro:link name="ring_finger_link" mass="0.01" mesh_path="package://arm_description/mesh/joint_finger.STL" mesh_material="red"/>
    <!-- ________________________________________________________________________________ -->

    <xacro:link name="phalanx_ring_finger_1_link" mass="0.01" mesh_path="package://arm_description/mesh/phalanx_finger_1.STL" mesh_material="red"/>
    <!-- ________________________________________________________________________________ -->

    <xacro:link name="phalanx_ring_finger_2_link" mass="0.01" mesh_path="package://arm_description/mesh/phalanx_finger_2.STL" mesh_material="red"/>
    <!-- ________________________________________________________________________________ -->

    <xacro:link name="phalanx_ring_finger_3_link" mass="0.01" mesh_path="package://arm_description/mesh/phalanx_finger_3.STL" mesh_material="red"/>
    <!-- ________________________________________________________________________________ -->

    <xacro:link name="mid_finger_link" mass="0.01" mesh_path="package://arm_description/mesh/joint_finger.STL" mesh_material="red"/>
    <!-- ________________________________________________________________________________ -->

    <xacro:link name="phalanx_mid_finger_1_link" mass="0.01" mesh_path="package://arm_description/mesh/phalanx_finger_1.STL" mesh_material="red"/>
    <!-- ________________________________________________________________________________ -->

    <xacro:link name="phalanx_mid_finger_2_link" mass="0.01" mesh_path="package://arm_description/mesh/phalanx_finger_2.STL" mesh_material="red"/>
    <!-- ________________________________________________________________________________ -->

    <xacro:link name="phalanx_mid_finger_3_link" mass="0.01" mesh_path="package://arm_description/mesh/phalanx_finger_3.STL" mesh_material="red"/>
    <!-- ________________________________________________________________________________ -->

    <xacro:link name="forefinger_link" mass="0.01" mesh_path="package://arm_description/mesh/joint_finger.STL" mesh_material="red"/>
    <!-- ________________________________________________________________________________ -->

    <xacro:link name="phalanx_forefinger_1_link" mass="0.01" mesh_path="package://arm_description/mesh/phalanx_finger_1.STL" mesh_material="red"/>
    <!-- ________________________________________________________________________________ -->

    <xacro:link name="phalanx_forefinger_2_link" mass="0.01" mesh_path="package://arm_description/mesh/phalanx_finger_2.STL" mesh_material="red"/>
    <!-- ________________________________________________________________________________ -->

    <xacro:link name="phalanx_forefinger_3_link" mass="0.01" mesh_path="package://arm_description/mesh/phalanx_finger_3.STL" mesh_material="red"/>
    <!-- ________________________________________________________________________________ -->
    <!-- Link end -->


    <!-- Joint -->
    <!-- ________________________________________________________________________________ -->
    <joint name="virtual_joint" type="fixed">
        <parent link="world_link"/>
        <child link="holder_link"/>
        <origin xyz="0 0 0" rpy="0 0 0"/>
    </joint>

    <!-- ________________________________________________________________________________ -->

    <joint name="joint_shoulder_Y" type="revolute">
        <parent link="holder_link"/>
        <child link="shoulder_Y_link"/>
        <origin xyz="0 -0.265 3.2" rpy="0 0 0"/>
        <axis xyz="0 1 0"/>
        <limit lower="-${PI/2}" upper="${PI/2}" effort="${effort}" velocity="${velocity}"/>
    </joint>

    <!-- ________________________________________________________________________________ -->

    <joint name="joint_shoulder_X" type="revolute">
        <parent link="shoulder_Y_link"/>
        <child link="shoulder_X_link"/>
        <origin xyz="0 -0.255 0.0" rpy="0 0 0"/>
        <axis xyz="1 0 0"/>
        <limit lower="-${PI/2}" upper="${PI/2}" effort="${effort}" velocity="${velocity}"/>
    </joint>

    <!-- ________________________________________________________________________________ -->

    <joint name="joint_shoulder" type="fixed">
        <parent link="shoulder_X_link"/>
        <child link="shoulder_link"/>
        <origin xyz="0 -0.1 0.0" rpy="0 0 0"/>
        <axis xyz="0 0 0"/>
    </joint>

    <!-- ________________________________________________________________________________ -->

    <joint name="joint_elbow_Z" type="revolute">
        <parent link="shoulder_link"/>
        <child link="elbow_Z_link"/>
        <origin xyz="0 -0.105 -0.7" rpy="0 0 0"/>
        <axis xyz="0 0 1"/>
        <limit lower="-${PI/2}" upper="${PI/2}" effort="${effort}" velocity="${velocity}"/>
    </joint>

    <!-- ________________________________________________________________________________ -->

    <joint name="joint_elbow_X" type="revolute">
        <parent link="elbow_Z_link"/>
        <child link="elbow_X_link"/>
        <origin xyz="0 -0.003 -0.24" rpy="0 0 0"/>
        <axis xyz="1 0 0"/>
        <limit lower="0" upper="${PI/2}" effort="${effort}" velocity="${velocity}"/>
    </joint>
    
    <!-- ________________________________________________________________________________ -->

    <joint name="joint_forearm" type="fixed">
        <parent link="elbow_X_link"/>
        <child link="forearm_link"/>
        <origin xyz="0 0 -0.1" rpy="0 0 0"/>
        <axis xyz="0 0 0"/>
    </joint>

    <!-- ________________________________________________________________________________ -->

    <joint name="joint_wrist_Z" type="revolute">
        <parent link="forearm_link"/>
        <child link="wrist_Z_link"/>
        <origin xyz="0.0 0.0 -0.75" rpy="0 0 0"/>
        <axis xyz="0 0 1"/>
        <limit lower="-${PI/2}" upper="${PI/2}" effort="${effort}" velocity="${velocity}"/>
    </joint>

    <!-- ________________________________________________________________________________ -->

    <joint name="joint_wrist_X" type="revolute">
        <parent link="wrist_Z_link"/>
        <child link="wrist_X_link"/>
        <origin xyz="0.0 0.0 -0.15" rpy="0 0 0"/>
        <axis xyz="1 0 0"/>
        <limit lower="-${PI/2}" upper="${PI/2}" effort="${effort}" velocity="${velocity}"/>
    </joint>

    <!-- ________________________________________________________________________________ -->

    <joint name="joint_hand" type="fixed">
        <parent link="wrist_X_link"/>
        <child link="hand_link"/>
        <origin xyz="0 -0.004 -0.25" rpy="0 0 0"/>
        <axis xyz="0 0 0"/>
    </joint>

    <!-- ________________________________________________________________________________ -->

    <joint name="joint_thumb" type="revolute">
        <parent link="hand_link"/>
        <child link="thumb_link"/>
        <origin xyz="0.101 0.009 0.11" rpy="0 0 0"/>
        <axis xyz="0 0 1"/>
        <limit lower="0" upper="${PI/2}" effort="${effort}" velocity="${velocity}"/>
    </joint>

    <!-- ________________________________________________________________________________ -->

    <joint name="joint_finger_thumb" type="revolute">
        <parent link="thumb_link"/>
        <child link="thumb_finger_link"/>
        <origin xyz="0.057 -0.0059 -0.014" rpy="0 -0.65 0"/>
        <axis xyz="0 1 0"/>
        <limit lower="-${PI/35}" upper="${PI/35}" effort="${effort}" velocity="${velocity}"/>
    </joint>

    <!-- ________________________________________________________________________________ -->

    <joint name="joint_phalanx_thumb_1" type="revolute">
        <parent link="thumb_finger_link"/>
        <child link="phalanx_thumb_1_link"/>
        <origin xyz="0.0 0.0 -0.02" rpy="0 0 0"/>
        <axis xyz="1 0 0"/>
        <limit lower="0" upper="${PI/2}" effort="${effort}" velocity="${velocity}"/>
    </joint>

    <!-- ________________________________________________________________________________ -->

    <joint name="joint_phalanx_thumb_2" type="revolute">
        <parent link="phalanx_thumb_1_link"/>
        <child link="phalanx_thumb_2_link"/>
        <origin xyz="0.0 0.0 -0.081" rpy="0 0 0"/>
        <axis xyz="1 0 0"/>
        <limit lower="0" upper="${PI/2}" effort="${effort}" velocity="${velocity}"/>
    </joint>

    <!-- ________________________________________________________________________________ -->

    <joint name="joint_lit_finger" type="revolute">
        <parent link="hand_link"/>
        <child link="lit_finger_link"/>
        <origin xyz="-0.1075 0.005 -0.004" rpy="0 0 0"/>
        <axis xyz="0 1 0"/>
        <limit lower="-${PI/35}" upper="${PI/35}" effort="${effort}" velocity="${velocity}"/>
    </joint>

    <!-- ________________________________________________________________________________ -->

    <joint name="joint_phalanx_lit_finger_1" type="revolute">
        <parent link="lit_finger_link"/>
        <child link="phalanx_lit_finger_1_link"/>
        <origin xyz="0.0 0.0 -0.025" rpy="0 0 0"/>
        <axis xyz="1 0 0"/>
        <limit lower="0" upper="${PI/2}" effort="${effort}" velocity="${velocity}"/>
    </joint>

    <!-- ________________________________________________________________________________ -->

    <joint name="joint_phalanx_lit_finger_2" type="revolute">
        <parent link="phalanx_lit_finger_1_link"/>
        <child link="phalanx_lit_finger_2_link"/>
        <origin xyz="0.0 0.0 -0.055" rpy="0 0 0"/>
        <axis xyz="1 0 0"/>
        <limit lower="0" upper="${PI/2}" effort="${effort}" velocity="${velocity}"/>
    </joint>

    <!-- ________________________________________________________________________________ -->

    <joint name="joint_phalanx_lit_finger_3" type="revolute">
        <parent link="phalanx_lit_finger_2_link"/>
        <child link="phalanx_lit_finger_3_link"/>
        <origin xyz="0.0 0.0 -0.055" rpy="0 0 0"/>
        <axis xyz="1 0 0"/>
        <limit lower="0" upper="${PI/2}" effort="${effort}" velocity="${velocity}"/>
    </joint>

    <!-- ________________________________________________________________________________ -->

    <joint name="joint_ring_finger" type="revolute">
        <parent link="hand_link"/>
        <child link="ring_finger_link"/>
        <origin xyz="-0.035 0.005 -0.017" rpy="0 0 0"/>
        <axis xyz="0 1 0"/>
        <limit lower="-${PI/35}" upper="${PI/35}" effort="${effort}" velocity="${velocity}"/>
    </joint>

    <!-- ________________________________________________________________________________ -->

    <joint name="joint_phalanx_ring_finger_1" type="revolute">
        <parent link="ring_finger_link"/>
        <child link="phalanx_ring_finger_1_link"/>
        <origin xyz="0.0 0.0 -0.025" rpy="0 0 0"/>
        <axis xyz="1 0 0"/>
        <limit lower="0" upper="${PI/2}" effort="${effort}" velocity="${velocity}"/>
    </joint>

    <!-- ________________________________________________________________________________ -->

    <joint name="joint_phalanx_ring_finger_2" type="revolute">
        <parent link="phalanx_ring_finger_1_link"/>
        <child link="phalanx_ring_finger_2_link"/>
        <origin xyz="0.0 0.0 -0.073" rpy="0 0 0"/>
        <axis xyz="1 0 0"/>
        <limit lower="0" upper="${PI/2}" effort="${effort}" velocity="${velocity}"/>
    </joint>

    <!-- ________________________________________________________________________________ -->

    <joint name="joint_phalanx_ring_finger_3" type="revolute">
        <parent link="phalanx_ring_finger_2_link"/>
        <child link="phalanx_ring_finger_3_link"/>
        <origin xyz="0.0 0.0 -0.073" rpy="0 0 0"/>
        <axis xyz="1 0 0"/>
        <limit lower="0" upper="${PI/2}" effort="${effort}" velocity="${velocity}"/>
    </joint>

    <!-- ________________________________________________________________________________ -->

    <joint name="joint_mid_finger" type="revolute">
        <parent link="hand_link"/>
        <child link="mid_finger_link"/>
        <origin xyz="0.035 0.005 -0.024" rpy="0 0 0"/>
        <axis xyz="0 1 0"/>
        <limit lower="-${PI/35}" upper="${PI/35}" effort="${effort}" velocity="${velocity}"/>
    </joint>

    <!-- ________________________________________________________________________________ -->

    <joint name="joint_phalanx_mid_finger_1" type="revolute">
        <parent link="mid_finger_link"/>
        <child link="phalanx_mid_finger_1_link"/>
        <origin xyz="0.0 0.0 -0.025" rpy="0 0 0"/>
        <axis xyz="1 0 0"/>
        <limit lower="0" upper="${PI/2}" effort="${effort}" velocity="${velocity}"/>
    </joint>

    <!-- ________________________________________________________________________________ -->

    <joint name="joint_phalanx_mid_finger_2" type="revolute">
        <parent link="phalanx_mid_finger_1_link"/>
        <child link="phalanx_mid_finger_2_link"/>
        <origin xyz="0.0 0.0 -0.073" rpy="0 0 0"/>
        <axis xyz="1 0 0"/>
        <limit lower="0" upper="${PI/2}" effort="${effort}" velocity="${velocity}"/>
    </joint>

    <!-- ________________________________________________________________________________ -->

    <joint name="joint_phalanx_mid_finger_3" type="revolute">
        <parent link="phalanx_mid_finger_2_link"/>
        <child link="phalanx_mid_finger_3_link"/>
        <origin xyz="0.0 0.0 -0.073" rpy="0 0 0"/>
        <axis xyz="1 0 0"/>
        <limit lower="0" upper="${PI/2}" effort="${effort}" velocity="${velocity}"/>
    </joint>

    <!-- ________________________________________________________________________________ -->

    <joint name="joint_forefinger" type="revolute">
        <parent link="hand_link"/>
        <child link="forefinger_link"/>
        <origin xyz="0.105 0.005 -0.016" rpy="0 0 0"/>
        <axis xyz="0 1 0"/>
        <limit lower="-${PI/35}" upper="${PI/35}" effort="${effort}" velocity="${velocity}"/>
    </joint>

    <!-- ________________________________________________________________________________ -->

    <joint name="joint_phalanx_forefinger_1" type="revolute">
        <parent link="forefinger_link"/>
        <child link="phalanx_forefinger_1_link"/>
        <origin xyz="0.0 0.0 -0.025" rpy="0 0 0"/>
        <axis xyz="1 0 0"/>
        <limit lower="0" upper="${PI/2}" effort="${effort}" velocity="${velocity}"/>
    </joint>

    <!-- ________________________________________________________________________________ -->

    <joint name="joint_phalanx_forefinger_2" type="revolute">
        <parent link="phalanx_forefinger_1_link"/>
        <child link="phalanx_forefinger_2_link"/>
        <origin xyz="0.0 0.0 -0.073" rpy="0 0 0"/>
        <axis xyz="1 0 0"/>
        <limit lower="0" upper="${PI/2}" effort="${effort}" velocity="${velocity}"/>
    </joint>

    <!-- ________________________________________________________________________________ -->

    <joint name="joint_phalanx_forefinger_3" type="revolute">
        <parent link="phalanx_forefinger_2_link"/>
        <child link="phalanx_forefinger_3_link"/>
        <origin xyz="0.0 0.0 -0.073" rpy="0 0 0"/>
        <axis xyz="1 0 0"/>
        <limit lower="0" upper="${PI/2}" effort="${effort}" velocity="${velocity}"/>
    </joint>

    <!-- ________________________________________________________________________________ -->
    <!-- Joint end -->
    
    
</robot>
